Traceback (most recent call last):
  File "<frozen runpy>", line 198, in _run_module_as_main
  File "<frozen runpy>", line 88, in _run_code
  File "/Library/Frame::1 - - [18/Oct/2025 19:25:20] "GET / HTTP/1.1" 200 -
::1 - - [18/Oct/2025 19:26:01] "GET / HTTP/1.1" 200 -
::1 - - [18/Oct/2025 19:26:36] "GET / HTTP/1.1" 200 -
::1 - - [18/Oct/2025 19:26:36] "GET /app.js HTTP/1.1" 200 -
::1 - - [18/Oct/2025 19:26:36] "GET /style.css HTTP/1.1" 200 -
::1 - - [18/Oct/2025 19:26:36] "GET /config.js HTTP/1.1" 200 -
::1 - - [18/Oct/2025 19:26:36] "GET /websites.js HTTP/1.1" 200 -
::1 - - [18/Oct/2025 19:26:37] code 404, message File not found
::1 - - [18/Oct/2025 19:26:37] "GET /favicon.ico HTTP/1.1" 404 -
 in server_bind
    return super().server_bind()
           ^^^^^^^^^^^^^^^^^^^^^
  File "/Library/Frameworks/Python.framework/Versions/3.12/lib/python3.12/http/server.py", line 136, in server_bind
    socketserver.TCPServer.server_bind(self)
  File "/Library/Frameworks/Python.framework/Versions/3.12/lib/python3.12/socketserver.py", line 473, in server_bind
    self.socket.bind(self.server_address)
OSError: [Errno 48] Address already in use
